[2023-03-03 11:30:21,568] {taskinstance.py:1159} INFO - Dependencies all met for <TaskInstance: avg_product_price.spark_submit manual__2023-03-03T11:27:04.771450+00:00 [queued]>
[2023-03-03 11:30:21,615] {taskinstance.py:1159} INFO - Dependencies all met for <TaskInstance: avg_product_price.spark_submit manual__2023-03-03T11:27:04.771450+00:00 [queued]>
[2023-03-03 11:30:21,615] {taskinstance.py:1356} INFO - 
--------------------------------------------------------------------------------
[2023-03-03 11:30:21,616] {taskinstance.py:1357} INFO - Starting attempt 2 of 2
[2023-03-03 11:30:21,617] {taskinstance.py:1358} INFO - 
--------------------------------------------------------------------------------
[2023-03-03 11:30:21,682] {taskinstance.py:1377} INFO - Executing <Task(SparkSubmitOperator): spark_submit> on 2023-03-03 11:27:04.771450+00:00
[2023-03-03 11:30:21,695] {standard_task_runner.py:52} INFO - Started process 1052 to run task
[2023-03-03 11:30:21,706] {standard_task_runner.py:79} INFO - Running: ['***', 'tasks', 'run', 'avg_product_price', 'spark_submit', 'manual__2023-03-03T11:27:04.771450+00:00', '--job-id', '10', '--raw', '--subdir', 'DAGS_FOLDER/avg_product_price.py', '--cfg-path', '/tmp/tmpcic9wfwu', '--error-file', '/tmp/tmpa9nd4yb4']
[2023-03-03 11:30:21,710] {standard_task_runner.py:80} INFO - Job 10: Subtask spark_submit
[2023-03-03 11:30:21,924] {task_command.py:370} INFO - Running <TaskInstance: avg_product_price.spark_submit manual__2023-03-03T11:27:04.771450+00:00 [running]> on host 7f5e973bdd66
[2023-03-03 11:30:41,622] {base_job.py:229} ERROR - LocalTaskJob heartbeat got an exception
Traceback (most recent call last):
  File "/usr/local/lib/python3.7/site-packages/sqlalchemy/engine/base.py", line 3141, in _wrap_pool_connect
    return fn()
  File "/usr/local/lib/python3.7/site-packages/sqlalchemy/pool/base.py", line 301, in connect
    return _ConnectionFairy._checkout(self)
  File "/usr/local/lib/python3.7/site-packages/sqlalchemy/pool/base.py", line 755, in _checkout
    fairy = _ConnectionRecord.checkout(pool)
  File "/usr/local/lib/python3.7/site-packages/sqlalchemy/pool/base.py", line 419, in checkout
    rec = pool._do_get()
  File "/usr/local/lib/python3.7/site-packages/sqlalchemy/pool/impl.py", line 259, in _do_get
    return self._create_connection()
  File "/usr/local/lib/python3.7/site-packages/sqlalchemy/pool/base.py", line 247, in _create_connection
    return _ConnectionRecord(self)
  File "/usr/local/lib/python3.7/site-packages/sqlalchemy/pool/base.py", line 362, in __init__
    self.__connect(first_connect_check=True)
  File "/usr/local/lib/python3.7/site-packages/sqlalchemy/pool/base.py", line 605, in __connect
    pool.logger.debug("Error on connect(): %s", e)
  File "/usr/local/lib/python3.7/site-packages/sqlalchemy/util/langhelpers.py", line 72, in __exit__
    with_traceback=exc_tb,
  File "/usr/local/lib/python3.7/site-packages/sqlalchemy/util/compat.py", line 211, in raise_
    raise exception
  File "/usr/local/lib/python3.7/site-packages/sqlalchemy/pool/base.py", line 599, in __connect
    connection = pool._invoke_creator(self)
  File "/usr/local/lib/python3.7/site-packages/sqlalchemy/engine/create.py", line 578, in connect
    return dialect.connect(*cargs, **cparams)
  File "/usr/local/lib/python3.7/site-packages/sqlalchemy/engine/default.py", line 583, in connect
    return self.dbapi.connect(*cargs, **cparams)
  File "/usr/local/lib/python3.7/site-packages/psycopg2/__init__.py", line 122, in connect
    conn = _connect(dsn, connection_factory=connection_factory, **kwasync)
psycopg2.OperationalError: could not translate host name "postgres" to address: Temporary failure in name resolution


The above exception was the direct cause of the following exception:

Traceback (most recent call last):
  File "/usr/local/lib/python3.7/site-packages/airflow/jobs/base_job.py", line 201, in heartbeat
    session.merge(self)
  File "/usr/local/lib/python3.7/site-packages/sqlalchemy/orm/session.py", line 2877, in merge
    _resolve_conflict_map=_resolve_conflict_map,
  File "/usr/local/lib/python3.7/site-packages/sqlalchemy/orm/session.py", line 2950, in _merge
    merged = self.get(mapper.class_, key[1], identity_token=key[2])
  File "/usr/local/lib/python3.7/site-packages/sqlalchemy/orm/session.py", line 2702, in get
    identity_token=identity_token,
  File "/usr/local/lib/python3.7/site-packages/sqlalchemy/orm/session.py", line 2800, in _get_impl
    load_options=load_options,
  File "/usr/local/lib/python3.7/site-packages/sqlalchemy/orm/loading.py", line 535, in load_on_pk_identity
    bind_arguments=bind_arguments,
  File "/usr/local/lib/python3.7/site-packages/sqlalchemy/orm/session.py", line 1669, in execute
    conn = self._connection_for_bind(bind, close_with_result=True)
  File "/usr/local/lib/python3.7/site-packages/sqlalchemy/orm/session.py", line 1520, in _connection_for_bind
    engine, execution_options
  File "/usr/local/lib/python3.7/site-packages/sqlalchemy/orm/session.py", line 747, in _connection_for_bind
    conn = bind.connect()
  File "/usr/local/lib/python3.7/site-packages/sqlalchemy/engine/base.py", line 3095, in connect
    return self._connection_cls(self, close_with_result=close_with_result)
  File "/usr/local/lib/python3.7/site-packages/sqlalchemy/engine/base.py", line 91, in __init__
    else engine.raw_connection()
  File "/usr/local/lib/python3.7/site-packages/sqlalchemy/engine/base.py", line 3174, in raw_connection
    return self._wrap_pool_connect(self.pool.connect, _connection)
  File "/usr/local/lib/python3.7/site-packages/sqlalchemy/engine/base.py", line 3145, in _wrap_pool_connect
    e, dialect, self
  File "/usr/local/lib/python3.7/site-packages/sqlalchemy/engine/base.py", line 2004, in _handle_dbapi_exception_noconnection
    sqlalchemy_exception, with_traceback=exc_info[2], from_=e
  File "/usr/local/lib/python3.7/site-packages/sqlalchemy/util/compat.py", line 211, in raise_
    raise exception
  File "/usr/local/lib/python3.7/site-packages/sqlalchemy/engine/base.py", line 3141, in _wrap_pool_connect
    return fn()
  File "/usr/local/lib/python3.7/site-packages/sqlalchemy/pool/base.py", line 301, in connect
    return _ConnectionFairy._checkout(self)
  File "/usr/local/lib/python3.7/site-packages/sqlalchemy/pool/base.py", line 755, in _checkout
    fairy = _ConnectionRecord.checkout(pool)
  File "/usr/local/lib/python3.7/site-packages/sqlalchemy/pool/base.py", line 419, in checkout
    rec = pool._do_get()
  File "/usr/local/lib/python3.7/site-packages/sqlalchemy/pool/impl.py", line 259, in _do_get
    return self._create_connection()
  File "/usr/local/lib/python3.7/site-packages/sqlalchemy/pool/base.py", line 247, in _create_connection
    return _ConnectionRecord(self)
  File "/usr/local/lib/python3.7/site-packages/sqlalchemy/pool/base.py", line 362, in __init__
    self.__connect(first_connect_check=True)
  File "/usr/local/lib/python3.7/site-packages/sqlalchemy/pool/base.py", line 605, in __connect
    pool.logger.debug("Error on connect(): %s", e)
  File "/usr/local/lib/python3.7/site-packages/sqlalchemy/util/langhelpers.py", line 72, in __exit__
    with_traceback=exc_tb,
  File "/usr/local/lib/python3.7/site-packages/sqlalchemy/util/compat.py", line 211, in raise_
    raise exception
  File "/usr/local/lib/python3.7/site-packages/sqlalchemy/pool/base.py", line 599, in __connect
    connection = pool._invoke_creator(self)
  File "/usr/local/lib/python3.7/site-packages/sqlalchemy/engine/create.py", line 578, in connect
    return dialect.connect(*cargs, **cparams)
  File "/usr/local/lib/python3.7/site-packages/sqlalchemy/engine/default.py", line 583, in connect
    return self.dbapi.connect(*cargs, **cparams)
  File "/usr/local/lib/python3.7/site-packages/psycopg2/__init__.py", line 122, in connect
    conn = _connect(dsn, connection_factory=connection_factory, **kwasync)
sqlalchemy.exc.OperationalError: (psycopg2.OperationalError) could not translate host name "postgres" to address: Temporary failure in name resolution

(Background on this error at: http://sqlalche.me/e/14/e3q8)
[2023-03-03 11:32:37,332] {taskinstance.py:1571} INFO - Exporting the following env vars:
AIRFLOW_CTX_DAG_OWNER=ayyoub
AIRFLOW_CTX_DAG_ID=avg_product_price
AIRFLOW_CTX_TASK_ID=spark_submit
AIRFLOW_CTX_EXECUTION_DATE=2023-03-03T11:27:04.771450+00:00
AIRFLOW_CTX_TRY_NUMBER=2
AIRFLOW_CTX_DAG_RUN_ID=manual__2023-03-03T11:27:04.771450+00:00
[2023-03-03 11:32:37,775] {base.py:68} INFO - Using connection ID 'spark-hadoop' for task execution.
[2023-03-03 11:32:37,782] {spark_submit.py:344} INFO - Spark-Submit cmd: spark-submit --master local[*] --name arrow-spark /hadoop-data/map_reduce/spark/average_price.py
[2023-03-03 11:32:42,173] {local_task_job.py:221} WARNING - State of this instance has been externally set to failed. Terminating instance.
[2023-03-03 11:32:42,179] {process_utils.py:129} INFO - Sending Signals.SIGTERM to group 1052. PIDs of all processes in the group: [1063, 1052]
[2023-03-03 11:32:42,180] {process_utils.py:80} INFO - Sending the signal Signals.SIGTERM to group 1052
[2023-03-03 11:32:42,183] {taskinstance.py:1541} ERROR - Received SIGTERM. Terminating subprocesses.
[2023-03-03 11:32:42,184] {spark_submit.py:620} INFO - Sending kill signal to spark-submit
[2023-03-03 11:32:42,278] {process_utils.py:75} INFO - Process psutil.Process(pid=1052, status='terminated', exitcode=0, started='11:30:21') (1052) terminated with exit code 0
[2023-03-03 11:33:42,100] {process_utils.py:143} WARNING - process psutil.Process(pid=1063, name='java', status='zombie', started='11:32:37') did not respond to SIGTERM. Trying SIGKILL
[2023-03-03 11:33:42,102] {process_utils.py:80} INFO - Sending the signal Signals.SIGKILL to group 1052
[2023-03-03 11:34:42,137] {process_utils.py:154} ERROR - Process psutil.Process(pid=1063, name='java', status='zombie', started='11:32:37') (1063) could not be killed. Giving up.
